<?xml version='1.0' encoding='utf-8'?>
<robot name="ur3e_robot">
  <link name="base_link" />
  <!-- IKPy/UR Teach Pendant variant: base_link is aligned with UR controller Base, not REP-103 base_link. -->
  <link name="base_link_inertia">
    <visual>
      <origin rpy="0 0 3.141592653589793" xyz="0 0 0" />
      <geometry>
        <mesh filename="package://ur_description/meshes/ur3e/visual/base.dae" />
      </geometry>
      <material name="LightGrey">
        <color rgba="0.7 0.7 0.7 1.0" />
      </material>
    </visual>
    <collision>
      <origin rpy="0 0 3.141592653589793" xyz="0 0 0" />
      <geometry>
        <mesh filename="package://ur_description/meshes/ur3e/collision/base.stl" />
      </geometry>
    </collision>
    <inertial>
      <mass value="2.0" />
      <origin rpy="0 0 0" xyz="0 0 0" />
      <inertia ixx="0.0030531654454" ixy="0.0" ixz="0.0" iyy="0.0030531654454" iyz="0.0" izz="0.005625" />
    </inertial>
  </link>
  <link name="shoulder_link">
    <visual>
      <origin rpy="0 0 3.141592653589793" xyz="0 0 0" />
      <geometry>
        <mesh filename="package://ur_description/meshes/ur3e/visual/shoulder.dae" />
      </geometry>
      <material name="LightGrey">
        <color rgba="0.7 0.7 0.7 1.0" />
      </material>
    </visual>
    <collision>
      <origin rpy="0 0 3.141592653589793" xyz="0 0 0" />
      <geometry>
        <mesh filename="package://ur_description/meshes/ur3e/collision/shoulder.stl" />
      </geometry>
    </collision>
    <inertial>
      <mass value="2.0" />
      <origin rpy="0 0 0" xyz="0 0 0" />
      <inertia ixx="0.008093163429399999" ixy="0.0" ixz="0.0" iyy="0.008093163429399999" iyz="0.0" izz="0.005625" />
    </inertial>
  </link>
  <link name="upper_arm_link">
    <visual>
      <origin rpy="1.5707963267948966 0 -1.5707963267948966" xyz="0 0 0.12" />
      <geometry>
        <mesh filename="package://ur_description/meshes/ur3e/visual/upperarm.dae" />
      </geometry>
      <material name="LightGrey">
        <color rgba="0.7 0.7 0.7 1.0" />
      </material>
    </visual>
    <collision>
      <origin rpy="1.5707963267948966 0 -1.5707963267948966" xyz="0 0 0.12" />
      <geometry>
        <mesh filename="package://ur_description/meshes/ur3e/collision/upperarm.stl" />
      </geometry>
    </collision>
    <inertial>
      <mass value="3.42" />
      <origin rpy="0 1.5707963267948966 0" xyz="-0.121825 0.0 0.12" />
      <inertia ixx="0.021728483221103233" ixy="0.0" ixz="0.0" iyy="0.021728483221103233" iyz="0.0" izz="0.00961875" />
    </inertial>
  </link>
  <link name="forearm_link">
    <visual>
      <origin rpy="1.5707963267948966 0 -1.5707963267948966" xyz="0 0 0.027" />
      <geometry>
        <mesh filename="package://ur_description/meshes/ur3e/visual/forearm.dae" />
      </geometry>
      <material name="LightGrey">
        <color rgba="0.7 0.7 0.7 1.0" />
      </material>
    </visual>
    <collision>
      <origin rpy="1.5707963267948966 0 -1.5707963267948966" xyz="0 0 0.027" />
      <geometry>
        <mesh filename="package://ur_description/meshes/ur3e/collision/forearm.stl" />
      </geometry>
    </collision>
    <inertial>
      <mass value="1.26" />
      <origin rpy="0 1.5707963267948966 0" xyz="-0.1066 0.0 0.027" />
      <inertia ixx="0.0065445675821719194" ixy="0.0" ixz="0.0" iyy="0.0065445675821719194" iyz="0.0" izz="0.00354375" />
    </inertial>
  </link>
  <link name="wrist_1_link">
    <visual>
      <origin rpy="1.5707963267948966 0 0" xyz="0 0 -0.104" />
      <geometry>
        <mesh filename="package://ur_description/meshes/ur3e/visual/wrist1.dae" />
      </geometry>
      <material name="LightGrey">
        <color rgba="0.7 0.7 0.7 1.0" />
      </material>
    </visual>
    <collision>
      <origin rpy="1.5707963267948966 0 0" xyz="0 0 -0.104" />
      <geometry>
        <mesh filename="package://ur_description/meshes/ur3e/collision/wrist1.stl" />
      </geometry>
    </collision>
    <inertial>
      <mass value="0.8" />
      <origin rpy="0 0 0" xyz="0 0 0" />
      <inertia ixx="0.002084999166" ixy="0.0" ixz="0.0" iyy="0.002084999166" iyz="0.0" izz="0.00225" />
    </inertial>
  </link>
  <link name="wrist_2_link">
    <visual>
      <origin rpy="0 0 0" xyz="0 0 -0.08535" />
      <geometry>
        <mesh filename="package://ur_description/meshes/ur3e/visual/wrist2.dae" />
      </geometry>
      <material name="LightGrey">
        <color rgba="0.7 0.7 0.7 1.0" />
      </material>
    </visual>
    <collision>
      <origin rpy="0 0 0" xyz="0 0 -0.08535" />
      <geometry>
        <mesh filename="package://ur_description/meshes/ur3e/collision/wrist2.stl" />
      </geometry>
    </collision>
    <inertial>
      <mass value="0.8" />
      <origin rpy="0 0 0" xyz="0 0 0" />
      <inertia ixx="0.002084999166" ixy="0.0" ixz="0.0" iyy="0.002084999166" iyz="0.0" izz="0.00225" />
    </inertial>
  </link>
  <link name="wrist_3_link">
    <visual>
      <origin rpy="1.5707963267948966 0 0" xyz="0 0 -0.0921" />
      <geometry>
        <mesh filename="package://ur_description/meshes/ur3e/visual/wrist3.dae" />
      </geometry>
      <material name="LightGrey">
        <color rgba="0.7 0.7 0.7 1.0" />
      </material>
    </visual>
    <collision>
      <origin rpy="1.5707963267948966 0 0" xyz="0 0 -0.0921" />
      <geometry>
        <mesh filename="package://ur_description/meshes/ur3e/collision/wrist3.stl" />
      </geometry>
    </collision>
    <inertial>
      <mass value="0.35" />
      <origin rpy="0 0 0" xyz="0.0 0.0 -0.02" />
      <inertia ixx="0.00013626661215999998" ixy="0.0" ixz="0.0" iyy="0.00013626661215999998" iyz="0.0" izz="0.0001792" />
    </inertial>
  </link>
  <joint name="base_link-base_link_inertia" type="fixed">
    <parent link="base_link" />
    <child link="base_link_inertia" />
    <origin rpy="0 0 0" xyz="0 0 0" />
  </joint>
  <joint name="shoulder_pan_joint" type="revolute">
    <parent link="base_link_inertia" />
    <child link="shoulder_link" />
    <origin rpy="0 0 0" xyz="0 0 0.15185" />
    <axis xyz="0 0 1" />
    <limit effort="56.0" lower="-6.283185307179586" upper="6.283185307179586" velocity="3.141592653589793" />
    <dynamics damping="0" friction="0" />
  </joint>
  <joint name="shoulder_lift_joint" type="revolute">
    <parent link="shoulder_link" />
    <child link="upper_arm_link" />
    <origin rpy="1.570796327 0 0" xyz="0 0 0" />
    <axis xyz="0 0 1" />
    <limit effort="56.0" lower="-6.283185307179586" upper="6.283185307179586" velocity="3.141592653589793" />
    <dynamics damping="0" friction="0" />
  </joint>
  <joint name="elbow_joint" type="revolute">
    <parent link="upper_arm_link" />
    <child link="forearm_link" />
    <origin rpy="0 0 0" xyz="-0.24355 0 0" />
    <axis xyz="0 0 1" />
    <limit effort="28.0" lower="-3.141592653589793" upper="3.141592653589793" velocity="3.141592653589793" />
    <dynamics damping="0" friction="0" />
  </joint>
  <joint name="wrist_1_joint" type="revolute">
    <parent link="forearm_link" />
    <child link="wrist_1_link" />
    <origin rpy="0 0 0" xyz="-0.2132 0 0.13105" />
    <axis xyz="0 0 1" />
    <limit effort="12.0" lower="-6.283185307179586" upper="6.283185307179586" velocity="6.283185307179586" />
    <dynamics damping="0" friction="0" />
  </joint>
  <joint name="wrist_2_joint" type="revolute">
    <parent link="wrist_1_link" />
    <child link="wrist_2_link" />
    <origin rpy="1.570796327 0 0" xyz="0 -0.08535 -1.750557762378351e-11" />
    <axis xyz="0 0 1" />
    <limit effort="12.0" lower="-6.283185307179586" upper="6.283185307179586" velocity="6.283185307179586" />
    <dynamics damping="0" friction="0" />
  </joint>
  <link name="active_tcp" />
  <joint name="wrist_3_link-active_tcp" type="fixed">
    <parent link="wrist_3_link" />
    <child link="active_tcp" />
    <origin xyz="0.00 0.00 0.174" rpy="0 0 0" />
  </joint>
  <joint name="wrist_3_joint" type="revolute">
    <parent link="wrist_2_link" />
    <child link="wrist_3_link" />
    <origin rpy="1.570796326589793 3.141592653589793 3.141592653589793" xyz="0 0.0921 -1.8890025766262e-11" />
    <axis xyz="0 0 1" />
    <limit effort="12.0" lower="-6.283185307179586" upper="6.283185307179586" velocity="6.283185307179586" />
    <dynamics damping="0" friction="0" />
  </joint>
</robot>